2021-10-20 00:09:19,770 INFO    MainThread:3537080 [internal.py:wandb_internal():86] W&B internal server running at pid: 3537080, started at: 2021-10-20 00:09:19.769077
2021-10-20 00:09:19,772 DEBUG   HandlerThread:3537080 [handler.py:handle_request():126] handle_request: check_version
2021-10-20 00:09:19,772 INFO    WriterThread:3537080 [datastore.py:open_for_write():77] open: /atlas/u/yanndubs/ISSL/logs/exp_dev/datarepr_mnist/augrepr_rotation_scale_shear_x-translation_y-translation/repr_base/dec_cluster_self_distillation/enc_resnet18/reg_cosine/optrepr_AdamW_lr1.0e-03_w1.0e-05/schedrepr_expdecay100/zdim_128/zs_1/beta_1.0e+00/seed_123/addrepr_None/jid_None_2021-10-20_00-08-28/wandb/run-20211020_000915-None_2021-10-20_00-08-28/run-None_2021-10-20_00-08-28.wandb
2021-10-20 00:09:19,777 DEBUG   SenderThread:3537080 [sender.py:send():185] send: header
2021-10-20 00:09:19,777 DEBUG   SenderThread:3537080 [sender.py:send_request():199] send_request: check_version
2021-10-20 00:09:19,860 DEBUG   SenderThread:3537080 [sender.py:send():185] send: run
2021-10-20 00:09:19,864 INFO    SenderThread:3537080 [sender.py:_maybe_setup_resume():427] checking resume status for issl/tmp/None_2021-10-20_00-08-28
2021-10-20 00:09:19,963 DEBUG   SenderThread:3537080 [git.py:repo():33] git repository is invalid
2021-10-20 00:09:20,065 ERROR   SenderThread:3537080 [internal_api.py:execute():135] 404 response executing GraphQL.
2021-10-20 00:09:20,065 ERROR   SenderThread:3537080 [internal_api.py:execute():136] {"errors":[{"message":"entity issl not found during upsertBucket","path":["upsertBucket"]}],"data":{"upsertBucket":null}}
2021-10-20 00:09:20,861 INFO    HandlerThread:3537080 [handler.py:finish():683] shutting down handler
2021-10-20 00:09:20,861 INFO    WriterThread:3537080 [datastore.py:close():281] close: /atlas/u/yanndubs/ISSL/logs/exp_dev/datarepr_mnist/augrepr_rotation_scale_shear_x-translation_y-translation/repr_base/dec_cluster_self_distillation/enc_resnet18/reg_cosine/optrepr_AdamW_lr1.0e-03_w1.0e-05/schedrepr_expdecay100/zdim_128/zs_1/beta_1.0e+00/seed_123/addrepr_None/jid_None_2021-10-20_00-08-28/wandb/run-20211020_000915-None_2021-10-20_00-08-28/run-None_2021-10-20_00-08-28.wandb
2021-10-20 00:09:20,862 ERROR   MainThread:3537080 [internal.py:wandb_internal():157] Thread SenderThread:
Traceback (most recent call last):
  File "/sailhome/yanndubs/anaconda3/envs/issl/lib/python3.9/site-packages/wandb/sdk/lib/retry.py", line 102, in __call__
    result = self._call_fn(*args, **kwargs)
  File "/sailhome/yanndubs/anaconda3/envs/issl/lib/python3.9/site-packages/wandb/sdk/internal/internal_api.py", line 138, in execute
    six.reraise(*sys.exc_info())
  File "/sailhome/yanndubs/anaconda3/envs/issl/lib/python3.9/site-packages/six.py", line 719, in reraise
    raise value
  File "/sailhome/yanndubs/anaconda3/envs/issl/lib/python3.9/site-packages/wandb/sdk/internal/internal_api.py", line 132, in execute
    return self.client.execute(*args, **kwargs)
  File "/sailhome/yanndubs/anaconda3/envs/issl/lib/python3.9/site-packages/wandb/vendor/gql-0.2.0/gql/client.py", line 52, in execute
    result = self._get_result(document, *args, **kwargs)
  File "/sailhome/yanndubs/anaconda3/envs/issl/lib/python3.9/site-packages/wandb/vendor/gql-0.2.0/gql/client.py", line 60, in _get_result
    return self.transport.execute(document, *args, **kwargs)
  File "/sailhome/yanndubs/anaconda3/envs/issl/lib/python3.9/site-packages/wandb/vendor/gql-0.2.0/gql/transport/requests.py", line 39, in execute
    request.raise_for_status()
  File "/sailhome/yanndubs/anaconda3/envs/issl/lib/python3.9/site-packages/requests/models.py", line 953, in raise_for_status
    raise HTTPError(http_error_msg, response=self)
requests.exceptions.HTTPError: 404 Client Error: Not Found for url: https://api.wandb.ai/graphql

During handling of the above exception, another exception occurred:

Traceback (most recent call last):
  File "/sailhome/yanndubs/anaconda3/envs/issl/lib/python3.9/site-packages/wandb/apis/normalize.py", line 24, in wrapper
    return func(*args, **kwargs)
  File "/sailhome/yanndubs/anaconda3/envs/issl/lib/python3.9/site-packages/wandb/sdk/internal/internal_api.py", line 1133, in upsert_run
    response = self.gql(mutation, variable_values=variable_values, **kwargs)
  File "/sailhome/yanndubs/anaconda3/envs/issl/lib/python3.9/site-packages/wandb/sdk/lib/retry.py", line 118, in __call__
    if not check_retry_fn(e):
  File "/sailhome/yanndubs/anaconda3/envs/issl/lib/python3.9/site-packages/wandb/util.py", line 815, in no_retry_auth
    raise CommError("Permission denied, ask the project owner to grant you access")
wandb.errors.CommError: Permission denied, ask the project owner to grant you access

During handling of the above exception, another exception occurred:

Traceback (most recent call last):
  File "/sailhome/yanndubs/anaconda3/envs/issl/lib/python3.9/site-packages/wandb/sdk/internal/internal_util.py", line 52, in run
    self._run()
  File "/sailhome/yanndubs/anaconda3/envs/issl/lib/python3.9/site-packages/wandb/sdk/internal/internal_util.py", line 102, in _run
    self._process(record)
  File "/sailhome/yanndubs/anaconda3/envs/issl/lib/python3.9/site-packages/wandb/sdk/internal/internal.py", line 290, in _process
    self._sm.send(record)
  File "/sailhome/yanndubs/anaconda3/envs/issl/lib/python3.9/site-packages/wandb/sdk/internal/sender.py", line 187, in send
    send_handler(record)
  File "/sailhome/yanndubs/anaconda3/envs/issl/lib/python3.9/site-packages/wandb/sdk/internal/sender.py", line 629, in send_run
    self._init_run(run, config_value_dict)
  File "/sailhome/yanndubs/anaconda3/envs/issl/lib/python3.9/site-packages/wandb/sdk/internal/sender.py", line 651, in _init_run
    server_run, inserted = self._api.upsert_run(
  File "/sailhome/yanndubs/anaconda3/envs/issl/lib/python3.9/site-packages/wandb/apis/normalize.py", line 62, in wrapper
    six.reraise(CommError, CommError(message, err), sys.exc_info()[2])
  File "/sailhome/yanndubs/anaconda3/envs/issl/lib/python3.9/site-packages/six.py", line 718, in reraise
    raise value.with_traceback(tb)
  File "/sailhome/yanndubs/anaconda3/envs/issl/lib/python3.9/site-packages/wandb/apis/normalize.py", line 24, in wrapper
    return func(*args, **kwargs)
  File "/sailhome/yanndubs/anaconda3/envs/issl/lib/python3.9/site-packages/wandb/sdk/internal/internal_api.py", line 1133, in upsert_run
    response = self.gql(mutation, variable_values=variable_values, **kwargs)
  File "/sailhome/yanndubs/anaconda3/envs/issl/lib/python3.9/site-packages/wandb/sdk/lib/retry.py", line 118, in __call__
    if not check_retry_fn(e):
  File "/sailhome/yanndubs/anaconda3/envs/issl/lib/python3.9/site-packages/wandb/util.py", line 815, in no_retry_auth
    raise CommError("Permission denied, ask the project owner to grant you access")
wandb.errors.CommError: Permission denied, ask the project owner to grant you access
2021-10-20 00:09:22,909 INFO    MainThread:3537080 [internal.py:handle_exit():76] Internal process exited
